Workbook

Sheet Summary
A1: Operation Blue Tiger: Milestone 1
A3: Mod | B3: Millennium Dawn: Developer Version
A4: Descriptor version | B4: 2.0.0 (changelog in progress: v2.0.1)
A5: HOI4 supported | B5: 1.19.*
A6: Repository | B6: D:\Projects\Millennium-Dawn
A7: Branch | B7: obt-taiwan-overhaul
A8: Base commit | B8: f198c6c8db (upstream main, 2 Oct 2026)
A11: Branch | B11: Focuses | C11: Total days | D11: In-game tested
A12: The 2000 Succession | B12: =COUNTIF(Focuses!$C$2:$C$248,A12) -> 41 | C12: =SUMIF(Focuses!$C$2:$C$248,A12,Focuses!$E$2:$E$248) -> 2485 | D12: =COUNTIFS(Focuses!$C$2:$C$248,A12,Focuses!$L$2:$L$248,"In-game tested") -> 0
A13: Democratic Fortress | B13: =COUNTIF(Focuses!$C$2:$C$248,A13) -> 30 | C13: =SUMIF(Focuses!$C$2:$C$248,A13,Focuses!$E$2:$E$248) -> 2030 | D13: =COUNTIFS(Focuses!$C$2:$C$248,A13,Focuses!$L$2:$L$248,"In-game tested") -> 0
A14: The National Army | B14: =COUNTIF(Focuses!$C$2:$C$248,A14) -> 50 | C14: =SUMIF(Focuses!$C$2:$C$248,A14,Focuses!$E$2:$E$248) -> 4095 | D14: =COUNTIFS(Focuses!$C$2:$C$248,A14,Focuses!$L$2:$L$248,"In-game tested") -> 0
A15: The Silicon Island | B15: =COUNTIF(Focuses!$C$2:$C$248,A15) -> 37 | C15: =SUMIF(Focuses!$C$2:$C$248,A15,Focuses!$E$2:$E$248) -> 2975 | D15: =COUNTIFS(Focuses!$C$2:$C$248,A15,Focuses!$L$2:$L$248,"In-game tested") -> 0
A16: Across the Strait | B16: =COUNTIF(Focuses!$C$2:$C$248,A16) -> 29 | C16: =SUMIF(Focuses!$C$2:$C$248,A16,Focuses!$E$2:$E$248) -> 2065 | D16: =COUNTIFS(Focuses!$C$2:$C$248,A16,Focuses!$L$2:$L$248,"In-game tested") -> 0
A17: The Pacific Lifeline | B17: =COUNTIF(Focuses!$C$2:$C$248,A17) -> 33 | C17: =SUMIF(Focuses!$C$2:$C$248,A17,Focuses!$E$2:$E$248) -> 2205 | D17: =COUNTIFS(Focuses!$C$2:$C$248,A17,Focuses!$L$2:$L$248,"In-game tested") -> 0
A18: Operation Blue Tiger | B18: =COUNTIF(Focuses!$C$2:$C$248,A18) -> 27 | C18: =SUMIF(Focuses!$C$2:$C$248,A18,Focuses!$E$2:$E$248) -> 1750 | D18: =COUNTIFS(Focuses!$C$2:$C$248,A18,Focuses!$L$2:$L$248,"In-game tested") -> 0
A19: Total | B19: =SUM(B12:B18) -> 247 | C19: =SUM(C12:C18) -> 17605 | D19: =SUM(D12:D18) -> 0
A21: National spirits | B21: =COUNTA(Spirits!A2:A49) -> 48
A22: Starting spirits | B22: =COUNTIF(Spirits!C2:C49,"Yes") -> 5
A24: How to use
A25: On the Focuses sheet, the yellow Status and Notes columns are yours to edit. Set Status from the dropdown (for example "In-game tested") and the In-game tested column above updates.
A26: Focus days are game days; HOI4 focus cost = days / 7.

Sheet Focuses
A1: Focus ID | B1: Name | C1: Branch | D1: Track | E1: Days | F1: Prerequisites | G1: Mutually exclusive | H1: Requirements | I1: Effects | J1: Content type | K1: AI weight | L1: Status | M1: Notes
A2: TAI_su_millennium_election | B2: The Millennium Election | C2: The 2000 Succession | D2: Shared trunk | E2: 35 | I2: +50 Political Power | J2: Historical / abstraction | K2: 10 | L2: Written
A3: TAI_su_heal_kmt_split | B3: Heal the KMT Split | C3: The 2000 Succession | D3: Shared trunk | E3: 35 | F3: The Millennium Election | G3: Let the Voters Decide | H3: Before 2000.3.18 | I3: Party 1 popularity +4%; Party 14 popularity -4%; -2% Stability | J3: Historical / abstraction | K3: 1 | L3: Written
A4: TAI_su_voters_decide | B4: Let the Voters Decide | C4: The 2000 Succession | D4: Shared trunk | E4: 35 | F4: The Millennium Election | G4: Heal the KMT Split | I4: +3% Stability; +25 Political Power | J4: Historical / abstraction | K4: 3 | L4: Written
A5: TAI_su_lee_legacy | B5: Lee Teng-hui's Legacy | C5: The 2000 Succession | D5: Shared trunk | E5: 35 | F5: The Millennium Election | I5: Taiwan-Centered Identity +5; Strait Tension (CHI) +3; +25 Political Power | J5: Historical / abstraction | K5: 1 | L5: Written
A6: TAI_su_peaceful_transfer | B6: The Peaceful Transfer of Power | C6: The 2000 Succession | D6: Shared trunk | E6: 70 | F6: Heal the KMT Split or Let the Voters Decide | H6: After the 2000 election | I6: +5% Stability; Military Confidence -5; +50 Political Power | J6: Historical / abstraction | K6: 5 | L6: Written
A7: TAI_su_form_cabinet | B7: Form the Cabinet | C7: The 2000 Succession | D7: Shared trunk | E7: 35 | F7: The Peaceful Transfer of Power | I7: Military Confidence +5; +25 Political Power | J7: Historical / abstraction | K7: 5 | L7: Written
A8: TAI_su_minority_government | B8: A Government Without a Majority | C8: The 2000 Succession | D8: Shared trunk | E8: 35 | F8: Form the Cabinet | G8: A Unified Government | H8: No LY majority | I8: Add spirit TAI_divided_government; +50 Political Power | J8: Historical / abstraction | K8: 5 | L8: Written
A9: TAI_su_unified_government | B9: A Unified Government | C9: The 2000 Succession | D9: Shared trunk | E9: 35 | F9: Form the Cabinet | G9: A Government Without a Majority | H9: LY majority | I9: +75 Political Power; -2% Stability | J9: Historical / abstraction | K9: 5 | L9: Written
A10: TAI_su_fourth_nuclear | B10: The Fourth Nuclear Plant Question | C10: The 2000 Succession | D10: Shared trunk | E10: 70 | F10: A Government Without a Majority or A Unified Government | I10: Research bonus nuclear_reactors; -2% Stability | J10: Historical / abstraction | K10: 1 | L10: Written
A11: TAI_su_2001_recession | B11: Weather the 2001 Recession | C11: The 2000 Succession | D11: Shared trunk | E11: 70 | F11: The Peaceful Transfer of Power | H11: After 2001.1.1 | I11: -3bn Treasury; +4% Stability; Timed spirit TAI_recession_relief (365 days) | J11: Historical / abstraction | K11: 3 | L11: Written
A12: TAI_su_ly_2001 | B12: The 2001 Legislative Election | C12: The 2000 Succession | D12: Shared trunk | E12: 35 | F12: A Government Without a Majority or A Unified Government | H12: After 2001.6.1 | I12: Ruling camp popularity +2%; +25 Political Power | J12: Historical / abstraction | K12: 1 | L12: Written
A13: TAI_su_second_mandate | B13: Seek a Second Mandate | C13: The 2000 Succession | D13: Shared trunk | E13: 70 | F13: The 2001 Legislative Election | H13: After 2003.6.1 | I13: Ruling camp popularity +2%; +2% Stability | J13: Historical / abstraction | K13: 1 | L13: Written
A14: TAI_su_heal_divided_island | B14: Healing a Divided Island | C14: The 2000 Succession | D14: Shared trunk | E14: 70 | F14: Seek a Second Mandate | H14: After 2004.3.21 | I14: +5% Stability; Pressure to Negotiate -3 | J14: Historical / abstraction | K14: 1 | L14: Written
A15: TAI_su_second_test | B15: Democracy's Second Test | C15: The 2000 Succession | D15: Shared trunk | E15: 70 | F15: Healing a Divided Island | H15: After 2007.6.1 | I15: +4% Stability; +50 Political Power | J15: Historical / abstraction | K15: 1 | L15: Written
A16: TAI_su_dpp_four_noes | B16: Four Noes and One Without | C16: The 2000 Succession | D16: DPP path | E16: 35 | F16: Form the Cabinet | H16: Pan-Green governing | I16: Strait Tension (CHI) -8; U.S. Confidence in Taipei +10; Cross-Strait Trust (CHI) +5 | J16: Historical / abstraction | K16: 5 | L16: Written
A17: TAI_su_dpp_cautious_revolutionary | B17: The Cautious Revolutionary | C17: The 2000 Succession | D17: DPP path | E17: 70 | F17: Four Noes and One Without | H17: Pan-Green governing | I17: +3% Stability; Military Confidence +5; +50 Political Power | J17: Historical / abstraction | K17: 3 | L17: Written
A18: TAI_su_dpp_taiwan_centered | B18: A Taiwan-Centered State | C18: The 2000 Succession | D18: DPP path | E18: 70 | F18: The Cautious Revolutionary | H18: Pan-Green governing | I18: Taiwan-Centered Identity +8; Strait Tension (CHI) +4; Cross-Strait Trust (CHI) -4 | J18: Historical / abstraction | K18: 1 | L18: Written
A19: TAI_su_dpp_referendum_act | B19: The Referendum Act | C19: The 2000 Succession | D19: DPP path | E19: 70 | F19: A Taiwan-Centered State | H19: Pan-Green governing; Can pass legislation (LY); After 2003.1.1 | I19: Taiwan-Centered Identity +3; U.S. Confidence in Taipei -5; +2% Stability | J19: Historical / abstraction | K19: 1 | L19: Written
A20: TAI_su_dpp_status_quo | B20: Reaffirm the Status Quo | C20: The 2000 Succession | D20: DPP path | E20: 70 | F20: The Referendum Act | G20: Name Rectification | H20: Pan-Green governing | I20: U.S. Confidence in Taipei +10; Strait Tension (CHI) -5; -3% Stability | J20: Historical / abstraction | K20: 3 | L20: Written
A21: TAI_su_dpp_name_rectification | B21: Name Rectification | C21: The 2000 Succession | D21: DPP path | E21: 70 | F21: The Referendum Act | G21: Reaffirm the Status Quo | H21: Pan-Green governing | I21: Taiwan-Centered Identity +10; Strait Tension (CHI) +10; U.S. Confidence in Taipei -10 | J21: Historical / abstraction | K21: 1 | L21: Written
A22: TAI_su_dpp_council_ceases | B22: The Council Ceases to Function | C22: The 2000 Succession | D22: DPP path | E22: 70 | F22: Name Rectification | H22: Pan-Green governing; Strait Tension above 49 | I22: Taiwan-Centered Identity +5; Strait Tension (CHI) +12; U.S. Confidence in Taipei -10 | J22: Historical / abstraction | K22: 1 | L22: Written
A23: TAI_su_dpp_un_bid | B23: Join the UN as Taiwan | C23: The 2000 Succession | D23: DPP path | E23: 70 | F23: The Council Ceases to Function | H23: Pan-Green governing; After 2007.1.1 | I23: Taiwan-Centered Identity +10; U.S. Confidence in Taipei -15; Strait Tension (CHI) +10 | J23: Historical / abstraction | K23: 0 | L23: Written
A24: TAI_su_dpp_clean_party | B24: A Clean Green Party | C24: The 2000 Succession | D24: DPP path | E24: 70 | F24: The Cautious Revolutionary | H24: Pan-Green governing | I24: Corruption -1 level; +2% Stability | J24: Historical / abstraction | K24: 3 | L24: Written
A25: TAI_su_kmt_rebuild | B25: Rebuild the Kuomintang | C25: The 2000 Succession | D25: KMT path | E25: 70 | F25: Form the Cabinet | H25: KMT governing | I25: +3% Stability; +50 Political Power | J25: Historical / abstraction | K25: 5 | L25: Written
A26: TAI_su_kmt_party_assets | B26: Settle the Party Assets | C26: The 2000 Succession | D26: KMT path | E26: 70 | F26: Rebuild the Kuomintang | H26: KMT governing | I26: Corruption -1 level; +3% Stability | J26: Historical / abstraction | K26: 1 | L26: Written
A27: TAI_su_kmt_technocrats | B27: A Government of Technocrats | C27: The 2000 Succession | D27: KMT path | E27: 70 | F27: Rebuild the Kuomintang | H27: KMT governing | I27: Reform Capacity +10; Timed spirit TAI_technocratic_cabinet (730 days) | J27: Historical / abstraction | K27: 3 | L27: Written
A28: TAI_su_kmt_pan_blue | B28: The Pan-Blue Coalition | C28: The 2000 Succession | D28: KMT path | E28: 35 | F28: Rebuild the Kuomintang | H28: KMT governing | I28: Party 1 popularity +2%; Party 14 popularity +1%; +25 Political Power | J28: Historical / abstraction | K28: 3 | L28: Written
A29: TAI_su_kmt_new_taiwanese | B29: We Are All New Taiwanese | C29: The 2000 Succession | D29: KMT path | E29: 70 | F29: The Pan-Blue Coalition | H29: KMT governing | I29: Taiwan-Centered Identity +4; +3% Stability | J29: Historical / abstraction | K29: 1 | L29: Written
A30: TAI_su_kmt_roc_framework | B30: Preserve the ROC Framework | C30: The 2000 Succession | D30: KMT path | E30: 70 | F30: We Are All New Taiwanese | H30: KMT governing | I30: Strait Tension (CHI) -5; Cross-Strait Trust (CHI) +5 | J30: Historical / abstraction | K30: 1 | L30: Written
A31: TAI_su_kmt_peace_framework | B31: Toward a Peace Framework | C31: The 2000 Succession | D31: KMT path | E31: 70 | F31: Preserve the ROC Framework | H31: KMT governing | I31: Cross-Strait Trust (CHI) +10; Strait Tension (CHI) -5; Mainland Economic Dependence +5 | J31: Historical / abstraction | K31: 1 | L31: Written
A32: TAI_su_kmt_consent | B32: No Unification Without Consent | C32: The 2000 Succession | D32: KMT path | E32: 70 | F32: Toward a Peace Framework | H32: KMT governing | I32: Pressure to Negotiate -10; +3% Stability | J32: Historical / abstraction | K32: 3 | L32: Written
A33: TAI_su_kmt_us_ties | B33: Keep Washington Close | C33: The 2000 Succession | D33: KMT path | E33: 70 | F33: A Government of Technocrats | H33: KMT governing | I33: U.S. Confidence in Taipei +8; U.S. Support for Taiwan (CHI) +3 | J33: Historical / abstraction | K33: 3 | L33: Written
... A42: TAI_su_pfp_washington | B42: Reassure Washington | C42: The 2000 Succession | D42: PFP path | E42: 70 | F42: A Pragmatic Strait | H42: PFP governing | I42: U.S. Confidence in Taipei +8 | J42: Historical / abstraction | K42: 1 | L42: Written
A43: TAI_df_root | B43: Consolidate the State, Not the Party | C43: Democratic Fortress | D43: Rule of law | E43: 70 | F43: The Peaceful Transfer of Power | I43: +3% Stability; National Coordination Capacity +5 | J43: Historical / abstraction | K43: 3 | L43: Written
A44: TAI_df_justice_minister | B44: A Reformist Justice Minister | C44: Democratic Fortress | D44: Rule of law | E44: 35 | F44: Consolidate the State, Not the Party | I44: Reform Capacity +5; Corruption -1 level | J44: Historical / abstraction | K44: 1 | L44: Written
A45: TAI_df_unshackle_prosecutors | B45: Unshackle the Prosecutors | C45: Democratic Fortress | D45: Rule of law | E45: 70 | F45: A Reformist Justice Minister | I45: Corruption -1 level; -2% Stability | J45: Historical / abstraction | K45: 1 | L45: Written
A46: TAI_df_professional_judiciary | B46: Professionalize the Judiciary | C46: Democratic Fortress | D46: Rule of law | E46: 70 | F46: Unshackle the Prosecutors | I46: +3% Stability | J46: Historical / abstraction | K46: 1 | L46: Written
A47: TAI_df_grand_justices | B47: Strengthen the Grand Justices | C47: Democratic Fortress | D47: Rule of law | E47: 70 | F47: Professionalize the Judiciary | I47: +3% Stability; +25 Political Power | J47: Historical / abstraction | K47: 1 | L47: Written
A48: TAI_df_special_division | B48: A Special Investigation Division | C48: Democratic Fortress | D48: Rule of law | E48: 70 | F48: Strengthen the Grand Justices | G48: Trust the Ordinary Prosecutors | I48: Corruption -1 level; -3% Stability | J48: Historical / abstraction | K48: 1 | L48: Written
...

Sheet Spirits
A1: Spirit ID | B1: Name | C1: Starting spirit | D1: Modifiers | E1: Granted by | F1: Description
A2: TAI_young_democracy | B2: Young Democracy | C2: Yes | D2: political_power_factor = -0.05; democratic_drift = 0.02 | E2: Game start | F2: Direct presidential elections are only four years old, and many institutions still carry habits from one-party rule. Public enthusiasm for democracy is high, but reform is slow and contested.
A3: TAI_party_army | B3: Legacy of the Party-Army | C3: Yes | D3: political_power_factor = -0.05; experience_gain_army = -0.10 | E3: Game start | F3: For decades the armed forces swore loyalty to the Kuomintang as well as the state. Many senior officers are uneasy about serving a government formed by another party.
A4: TAI_party_army_reduced | B4: Legacy of the Party-Army | C4: No | D4: experience_gain_army = -0.05 | E4: Nationalize the Armed Forces | F4: The armed forces now serve the constitution in law, but old habits fade slowly.
A5: TAI_did_legacy | B5: Defense-in-Depth Legacy | C5: Yes | D5: army_defence_factor = 0.05; max_dig_in = 2; naval_damage_factor = -0.05; air_attack_factor = -0.05; planning_speed = -0.05 | E5: Game start | F5: Our forces were built to defeat a landing on the beaches. They dig in well but are poorly prepared to strike at sea or fight as a joint force.
A6: TAI_did_legacy_reformed | B6: Defense-in-Depth Legacy | C6: No | D6: army_defence_factor = 0.05; max_dig_in = 2 | E6: Joint Command Reform | F6: Joint command has removed the worst seams between the services, but our doctrine still centers on the beaches.
A7: TAI_uneven_reserves | B7: Large but Uneven Reserve System | C7: Yes | D7: training_time_factor = 0.10; army_org_factor = -0.03 | E7: Game start | F7: Millions of men are listed as reservists after conscription, but refresher training is short and irregular.
A8: TAI_limited_absorption | B8: Advanced Procurement, Limited Absorption | C8: Yes | D8: experience_gain_air = -0.05; experience_gain_navy = -0.05 | E8: Game start | F8: The F-16s, Mirage 2000-5s and new frigates of the 1990s arrived faster than crews, mechanics and spare parts could keep up.
A9: TAI_divided_government | B9: Divided Government | C9: No | D9: political_power_factor = -0.10; stability_factor = -0.03 | E9: A Government Without a Majority; Reunite the Pan-Blue Camp; Reform the Legislative Yuan | F9: The president's party does not control the Legislative Yuan. Every budget and reform must be negotiated with the opposition.
A10: TAI_consolidated_democracy | B10: Consolidated Democracy | C10: No | D10: stability_factor = 0.05; political_power_factor = 0.05; foreign_influence_defense_modifier = 0.15; drift_defence_factor = 0.15 | E10: Democracy in the Political DNA | F10: Peaceful alternation in power, independent courts and a free press are now accepted by every major party.
A11: TAI_recession_relief | B11: Recession Relief | C11: No | D11: stability_factor = 0.03 | E11: Weather the 2001 Recession | F11: Job programmes and targeted relief keep the technology downturn from becoming a social crisis.
A12: TAI_technocratic_cabinet | B12: A Cabinet of Technocrats | C12: No | D12: research_speed_factor = 0.03; production_factory_efficiency_gain_factor = 0.03; political_power_factor = -0.03 | E12: A Government of Technocrats | F12: Experienced administrators run the ministries, trading political charisma for steady delivery.
... A49: TAI_impossible_to_coerce | B49: Impossible to Coerce | C49: No | D49: stability_factor = 0.05; war_support_factor = 0.05; foreign_influence_defense_modifier = 0.20; army_core_defence_factor = 0.05 | E49: Impossible to Coerce at an Acceptable Price | F49: Taiwan does not have to be impossible to hurt. It has to be impossible to coerce at an acceptable price.

Sheet Variables
A1: Variable | B1: Meaning | C1: Scope | D1: Start value | E1: Status | F1: Source
A2: TAI_us_confidence | B2: U.S. Confidence in Taipei | C2: TAI | D2: 60 | E2: New; moved by focuses | F2: Pass VI (separate from commitment)
A3: TAI_military_confidence | B3: Military Confidence | C3: TAI | D3: 55 | E3: New; moved by focuses | F3: Pass IV
A4: TAI_reform_capacity | B4: Reform Capacity | C4: TAI | D4: 50 | E4: New; moved by focuses | F4: Pass IV
A5: TAI_mainland_dependence | B5: Mainland Economic Dependence | C5: TAI | D5: 30 | E5: New; moved by focuses | F5: Pass VI (separate from trust)
A6: TAI_semiconductor_security | B6: Semiconductor Supply Security | C6: TAI | D6: 85 | E6: New; moved by focuses | F6: Directive section 4
A7: TAI_pressure_to_negotiate | B7: Pressure to Negotiate | C7: TAI | D7: 5 | E7: New; moved by focuses | F7: Pass VI
A8: TAI_taiwanese_identity | B8: Taiwan-Centered Identity | C8: TAI | D8: 40 | E8: New; moved by focuses | F8: Pass III / thesis
A9: TAI_national_coordination | B9: National Coordination Capacity | C9: TAI | D9: 40 | E9: New; moved by focuses | F9: Pass VI (30-page draft)
A10: TAI_defense_posture | B10: Defense posture (1 DiD, 2 Active, 3 Hard ROC, 4 Asymmetric, 5 Hybrid) | C10: TAI | D10: 1 | E10: New; set by doctrine focuses | F10: Pass IV
A11: CHI_taiwan_strait_tension | B11: Cross-Strait Tension | C11: CHI | D11: 20 | E11: Existing MD variable, reused | F11: Millennium Dawn
A12: CHI_TAI_trust | B12: Cross-Strait political trust | C12: CHI | D12: 50 | E12: Existing MD variable, reused | F12: Millennium Dawn
A13: CHI_taiwan_us_support | B13: U.S. Security Commitment | C13: CHI | D13: 85 | E13: Existing MD variable, reused | F13: Millennium Dawn
A15: Start values are proposed balance values on 0-100 scales, not historical measurements. CHI values are Millennium Dawn's existing history settings.

Sheet Files Changed
A1: File | B1: Change | C1: Lines added | D1: Lines deleted
A2: common/national_focus/05_taiwan.txt | B2: New file: taiwan_focus tree, 247 focuses | C2: 5516 | D2: 0
A3: common/ideas/05_taiwan.txt | B3: Added 54 Blue Tiger national spirits | C3: 467 | D3: 0
A4: common/scripted_triggers/99_TAI_scripted_triggers.txt | B4: Added 7 triggers (government camp, LY majority, roots ready) | C4: 65 | D4: 0
A5: common/scripted_effects/99_TAI_scripted_effects.txt | B5: Added 3 effects | C5: 31 | D5: 0
A6: history/countries/TAI - Taiwan.txt | B6: Added 5 starting spirits and 9 state variables | C6: 15 | D6: 0
A7: localisation/english/MD_focus_TAI_l_english.yml | B7: Added all focus, spirit, variable and tooltip text | C7: 611 | D7: 0
A8: Changelog.txt | B8: Added one line under v2.0.1 Content | C8: 1 | D8: 0
A9: Total | C9: =SUM(C2:C8) -> 6706 | D9: =SUM(D2:D8) -> 0
A11: Line counts from git diff --stat on branch obt-taiwan-overhaul, 16 Oct 2026. All changes are uncommitted.
